Workbook
Name Slicer_Month: #N/A
Name Slicer_Year: #N/A

Sheet DASHBOARD
B45: https://exceltable.com/

Sheet Total Capital
B46: https://exceltable.com/

Sheet Cost and Income
C46: https://exceltable.com/

Sheet Income vs Capital
B47: https://exceltable.com/

Sheet Leverage Index
D46: https://exceltable.com/

Sheet Traffic Top Rank
B46: https://exceltable.com/

Sheet Capital Efficiency
C48: https://exceltable.com/

Sheet DASHBOARD Light
C47: https://exceltable.com/

Sheet Total Capital Light
C47: https://exceltable.com/

Sheet Cost and Income Light
D46: https://exceltable.com/

Sheet Income vs Capital Light
C46: https://exceltable.com/

Sheet Leverage Index Light
C46: https://exceltable.com/

Sheet Traffic Top Rank Light
C47: https://exceltable.com/

Sheet Capital Efficiency Light
C48: https://exceltable.com/

Sheet Processing
A1: Num Month | B1: Month | C1: Planned | D1: Actual | E1: Passed P | F1: Required Pace P | G1: Marker P | H1: Before P | I1: Before A | J1: Marker A | L1: Month | M1: Expenses | N1: Income | O1: Cursor | Q1: Capital Accumulation | T1: Dashboard
A2: 1 | B2: JAN | C2: =GETPIVOTDATA(""&C$1,Control!$A$20,"Month",""&$B2) -> 3800 | D2: =GETPIVOTDATA(""&D$1,Control!$A$20,"Month",""&$B2) -> 2700 | E2: =IF(GETPIVOTDATA("Max of Num Month",Control!$A$3)>=$A2,C2,NA()) -> 3800 | F2: =IF(GETPIVOTDATA("Max of Num Month",Control!$A$3)<=$A2,C2,NA()) -> #N/A | G2: =IFERROR(GETPIVOTDATA(""&C$1,Control!$A$3,"Month",""&$B2),NA()) -> #N/A | H2: =IF(GETPIVOTDATA("Max of Num Month",Control!$A$3)>=$A2,C2,NA()) -> 3800 | I2: =IF(GETPIVOTDATA("Max of Num Month",Control!$A$3)>=$A2,D2,NA()) -> 2700 | J2: =IFERROR(GETPIVOTDATA(""&D$1,Control!$A$3,"Month",""&$B2),NA()) -> #N/A | L2: JAN | M2: =GETPIVOTDATA(""&M$1,Control!$A$20,"Month",""&$L2) -> 2300 | N2: =GETPIVOTDATA(""&N$1,Control!$A$20,"Month",""&$L2) -> 2000 | O2: =IFERROR(GETPIVOTDATA(""&N$1,Control!$A$3,"Month",""&$L2),NA()) -> #N/A | Q2: Starting Capital | R2: 1000 | T2: Total Capital | U2: =J14 -> 13700 | V2: ="of "&TEXT("100000","$#,###") -> of $100,000
A3: 2 | B3: FEB | C3: =GETPIVOTDATA(""&C$1,Control!$A$20,"Month",""&$B3) -> 4100 | D3: =GETPIVOTDATA(""&D$1,Control!$A$20,"Month",""&$B3) -> 2950 | E3: =IF(GETPIVOTDATA("Max of Num Month",Control!$A$3)>=$A3,C3,NA()) -> 4100 | F3: =IF(GETPIVOTDATA("Max of Num Month",Control!$A$3)<=$A3,C3,NA()) -> #N/A | G3: =IFERROR(GETPIVOTDATA(""&C$1,Control!$A$3,"Month",""&$B3),NA()) -> #N/A | H3: =IF(GETPIVOTDATA("Max of Num Month",Control!$A$3)>=$A3,C3,NA()) -> 4100 | I3: =IF(GETPIVOTDATA("Max of Num Month",Control!$A$3)>=$A3,D3,NA()) -> 2950 | J3: =IFERROR(GETPIVOTDATA(""&D$1,Control!$A$3,"Month",""&$B3),NA()) -> #N/A | L3: FEB | M3: =GETPIVOTDATA(""&M$1,Control!$A$20,"Month",""&$L3) -> 2700 | N3: =GETPIVOTDATA(""&N$1,Control!$A$20,"Month",""&$L3) -> 1600 | O3: =IFERROR(GETPIVOTDATA(""&N$1,Control!$A$3,"Month",""&$L3),NA()) -> #N/A | Q3: Income | R3: =N14 -> 7840 | T3: Cost & Income | U3: =M14 -> 5460
A4: 3 | B4: MAR | C4: =GETPIVOTDATA(""&C$1,Control!$A$20,"Month",""&$B4) -> 5100 | D4: =GETPIVOTDATA(""&D$1,Control!$A$20,"Month",""&$B4) -> 3600 | E4: =IF(GETPIVOTDATA("Max of Num Month",Control!$A$3)>=$A4,C4,NA()) -> 5100 | F4: =IF(GETPIVOTDATA("Max of Num Month",Control!$A$3)<=$A4,C4,NA()) -> #N/A | G4: =IFERROR(GETPIVOTDATA(""&C$1,Control!$A$3,"Month",""&$B4),NA()) -> #N/A | H4: =IF(GETPIVOTDATA("Max of Num Month",Control!$A$3)>=$A4,C4,NA()) -> 5100 | I4: =IF(GETPIVOTDATA("Max of Num Month",Control!$A$3)>=$A4,D4,NA()) -> 3600 | J4: =IFERROR(GETPIVOTDATA(""&D$1,Control!$A$3,"Month",""&$B4),NA()) -> #N/A | L4: MAR | M4: =GETPIVOTDATA(""&M$1,Control!$A$20,"Month",""&$L4) -> 2620 | N4: =GETPIVOTDATA(""&N$1,Control!$A$20,"Month",""&$L4) -> 1400 | O4: =IFERROR(GETPIVOTDATA(""&N$1,Control!$A$3,"Month",""&$L4),NA()) -> #N/A | Q4: Investments | R4: =E17 -> 3042 | T4: Income vs Capital | U4: =N14/SUM(J14,N14) -> 0.363974 | V4: =1-U4 -> 0.636026
A5: 4 | B5: APR | C5: =GETPIVOTDATA(""&C$1,Control!$A$20,"Month",""&$B5) -> 5800 | D5: =GETPIVOTDATA(""&D$1,Control!$A$20,"Month",""&$B5) -> 4300 | E5: =IF(GETPIVOTDATA("Max of Num Month",Control!$A$3)>=$A5,C5,NA()) -> 5800 | F5: =IF(GETPIVOTDATA("Max of Num Month",Control!$A$3)<=$A5,C5,NA()) -> #N/A | G5: =IFERROR(GETPIVOTDATA(""&C$1,Control!$A$3,"Month",""&$B5),NA()) -> 5800 | H5: =IF(GETPIVOTDATA("Max of Num Month",Control!$A$3)>=$A5,C5,NA()) -> 5800 | I5: =IF(GETPIVOTDATA("Max of Num Month",Control!$A$3)>=$A5,D5,NA()) -> 4300 | J5: =IFERROR(GETPIVOTDATA(""&D$1,Control!$A$3,"Month",""&$B5),NA()) -> 4300 | L5: APR | M5: =GETPIVOTDATA(""&M$1,Control!$A$20,"Month",""&$L5) -> 2100 | N5: =GETPIVOTDATA(""&N$1,Control!$A$20,"Month",""&$L5) -> 1800 | O5: =IFERROR(GETPIVOTDATA(""&N$1,Control!$A$3,"Month",""&$L5),NA()) -> 1800 | Q5: Cash Reserve | R5: =E18 -> 3647 | T5: Leverage Index | U5: =ROUND(AVERAGE(N17:N24),0)&"/100" -> 227/100
A6: 5 | B6: MAY | C6: =GETPIVOTDATA(""&C$1,Control!$A$20,"Month",""&$B6) -> 6300 | D6: =GETPIVOTDATA(""&D$1,Control!$A$20,"Month",""&$B6) -> 4000 | E6: =IF(GETPIVOTDATA("Max of Num Month",Control!$A$3)>=$A6,C6,NA()) -> 6300 | F6: =IF(GETPIVOTDATA("Max of Num Month",Control!$A$3)<=$A6,C6,NA()) -> #N/A | G6: =IFERROR(GETPIVOTDATA(""&C$1,Control!$A$3,"Month",""&$B6),NA()) -> 6300 | H6: =IF(GETPIVOTDATA("Max of Num Month",Control!$A$3)>=$A6,C6,NA()) -> 6300 | I6: =IF(GETPIVOTDATA("Max of Num Month",Control!$A$3)>=$A6,D6,NA()) -> 4000 | J6: =IFERROR(GETPIVOTDATA(""&D$1,Control!$A$3,"Month",""&$B6),NA()) -> 4000 | L6: MAY | M6: =GETPIVOTDATA(""&M$1,Control!$A$20,"Month",""&$L6) -> 1660 | N6: =GETPIVOTDATA(""&N$1,Control!$A$20,"Month",""&$L6) -> 2800 | O6: =IFERROR(GETPIVOTDATA(""&N$1,Control!$A$3,"Month",""&$L6),NA()) -> 2800 | Q6: Digital Craft | R6: =E19 -> 4271 | T6: Traffic Top Rank | U6: =I17 -> 20821 | V6: =H17 -> Blog Articles
A7: 6 | B7: JUN | C7: =GETPIVOTDATA(""&C$1,Control!$A$20,"Month",""&$B7) -> 7700 | D7: =GETPIVOTDATA(""&D$1,Control!$A$20,"Month",""&$B7) -> 5400 | E7: =IF(GETPIVOTDATA("Max of Num Month",Control!$A$3)>=$A7,C7,NA()) -> 7700 | F7: =IF(GETPIVOTDATA("Max of Num Month",Control!$A$3)<=$A7,C7,NA()) -> 7700 | G7: =IFERROR(GETPIVOTDATA(""&C$1,Control!$A$3,"Month",""&$B7),NA()) -> 7700 | H7: =IF(GETPIVOTDATA("Max of Num Month",Control!$A$3)>=$A7,C7,NA()) -> 7700 | I7: =IF(GETPIVOTDATA("Max of Num Month",Control!$A$3)>=$A7,D7,NA()) -> 5400 | J7: =IFERROR(GETPIVOTDATA(""&D$1,Control!$A$3,"Month",""&$B7),NA()) -> 5400 | L7: JUN | M7: =GETPIVOTDATA(""&M$1,Control!$A$20,"Month",""&$L7) -> 1700 | N7: =GETPIVOTDATA(""&N$1,Control!$A$20,"Month",""&$L7) -> 3240 | O7: =IFERROR(GETPIVOTDATA(""&N$1,Control!$A$3,"Month",""&$L7),NA()) -> 3240 | Q7: Other Assets | R7: =E20 -> 2740 | T7: Capital Efficiency | U7: =Q12 -> 21.67
A8: 7 | B8: JUL | C8: =GETPIVOTDATA(""&C$1,Control!$A$20,"Month",""&$B8) -> 8900 | D8: =GETPIVOTDATA(""&D$1,Control!$A$20,"Month",""&$B8) -> 6300 | E8: =IF(GETPIVOTDATA("Max of Num Month",Control!$A$3)>=$A8,C8,NA()) -> #N/A | F8: =IF(GETPIVOTDATA("Max of Num Month",Control!$A$3)<=$A8,C8,NA()) -> 8900 | G8: =IFERROR(GETPIVOTDATA(""&C$1,Control!$A$3,"Month",""&$B8),NA()) -> #N/A | H8: =IF(GETPIVOTDATA("Max of Num Month",Control!$A$3)>=$A8,C8,NA()) -> #N/A | I8: =IF(GETPIVOTDATA("Max of Num Month",Control!$A$3)>=$A8,D8,NA()) -> #N/A | J8: =IFERROR(GETPIVOTDATA(""&D$1,Control!$A$3,"Month",""&$B8),NA()) -> #N/A | L8: JUL | M8: =GETPIVOTDATA(""&M$1,Control!$A$20,"Month",""&$L8) -> 2300 | N8: =GETPIVOTDATA(""&N$1,Control!$A$20,"Month",""&$L8) -> 3200 | O8: =IFERROR(GETPIVOTDATA(""&N$1,Control!$A$3,"Month",""&$L8),NA()) -> #N/A | Q8: Expenses | R8: =0-M14 -> -5460
A9: 8 | B9: AUG | C9: =GETPIVOTDATA(""&C$1,Control!$A$20,"Month",""&$B9) -> 9600 | D9: =GETPIVOTDATA(""&D$1,Control!$A$20,"Month",""&$B9) -> 5900 | E9: =IF(GETPIVOTDATA("Max of Num Month",Control!$A$3)>=$A9,C9,NA()) -> #N/A | F9: =IF(GETPIVOTDATA("Max of Num Month",Control!$A$3)<=$A9,C9,NA()) -> 9600 | G9: =IFERROR(GETPIVOTDATA(""&C$1,Control!$A$3,"Month",""&$B9),NA()) -> #N/A | H9: =IF(GETPIVOTDATA("Max of Num Month",Control!$A$3)>=$A9,C9,NA()) -> #N/A | I9: =IF(GETPIVOTDATA("Max of Num Month",Control!$A$3)>=$A9,D9,NA()) -> #N/A | J9: =IFERROR(GETPIVOTDATA(""&D$1,Control!$A$3,"Month",""&$B9),NA()) -> #N/A | L9: AUG | M9: =GETPIVOTDATA(""&M$1,Control!$A$20,"Month",""&$L9) -> 3020 | N9: =GETPIVOTDATA(""&N$1,Control!$A$20,"Month",""&$L9) -> 3000 | O9: =IFERROR(GETPIVOTDATA(""&N$1,Control!$A$3,"Month",""&$L9),NA()) -> #N/A | Q9: Current Capital | R9: =SUM(R3:R8) -> 16080
A10: 9 | B10: SEP | C10: =GETPIVOTDATA(""&C$1,Control!$A$20,"Month",""&$B10) -> 11900 | D10: =GETPIVOTDATA(""&D$1,Control!$A$20,"Month",""&$B10) -> 8100 | E10: =IF(GETPIVOTDATA("Max of Num Month",Control!$A$3)>=$A10,C10,NA()) -> #N/A | F10: =IF(GETPIVOTDATA("Max of Num Month",Control!$A$3)<=$A10,C10,NA()) -> 11900 | G10: =IFERROR(GETPIVOTDATA(""&C$1,Control!$A$3,"Month",""&$B10),NA()) -> #N/A | H10: =IF(GETPIVOTDATA("Max of Num Month",Control!$A$3)>=$A10,C10,NA()) -> #N/A | I10: =IF(GETPIVOTDATA("Max of Num Month",Control!$A$3)>=$A10,D10,NA()) -> #N/A | J10: =IFERROR(GETPIVOTDATA(""&D$1,Control!$A$3,"Month",""&$B10),NA()) -> #N/A | L10: SEP | M10: =GETPIVOTDATA(""&M$1,Control!$A$20,"Month",""&$L10) -> 3180 | N10: =GETPIVOTDATA(""&N$1,Control!$A$20,"Month",""&$L10) -> 3200 | O10: =IFERROR(GETPIVOTDATA(""&N$1,Control!$A$3,"Month",""&$L10),NA()) -> #N/A | T10: Goal Progress to $100,000 | U10: =J14/100000 -> 0.137 | V10: =1-U10 -> 0.863
A11: 10 | B11: OCT | C11: =GETPIVOTDATA(""&C$1,Control!$A$20,"Month",""&$B11) -> 13700 | D11: =GETPIVOTDATA(""&D$1,Control!$A$20,"Month",""&$B11) -> 9600 | E11: =IF(GETPIVOTDATA("Max of Num Month",Control!$A$3)>=$A11,C11,NA()) -> #N/A | F11: =IF(GETPIVOTDATA("Max of Num Month",Control!$A$3)<=$A11,C11,NA()) -> 13700 | G11: =IFERROR(GETPIVOTDATA(""&C$1,Control!$A$3,"Month",""&$B11),NA()) -> #N/A | H11: =IF(GETPIVOTDATA("Max of Num Month",Control!$A$3)>=$A11,C11,NA()) -> #N/A | I11: =IF(GETPIVOTDATA("Max of Num Month",Control!$A$3)>=$A11,D11,NA()) -> #N/A | J11: =IFERROR(GETPIVOTDATA(""&D$1,Control!$A$3,"Month",""&$B11),NA()) -> #N/A | L11: OCT | M11: =GETPIVOTDATA(""&M$1,Control!$A$20,"Month",""&$L11) -> 2700 | N11: =GETPIVOTDATA(""&N$1,Control!$A$20,"Month",""&$L11) -> 4000 | O11: =IFERROR(GETPIVOTDATA(""&N$1,Control!$A$3,"Month",""&$L11),NA()) -> #N/A | Q11: Capital Velocity | T11: Current Capital | U11: =J14 -> 13700
A12: 11 | B12: NOV | C12: =GETPIVOTDATA(""&C$1,Control!$A$20,"Month",""&$B12) -> 14800 | D12: =GETPIVOTDATA(""&D$1,Control!$A$20,"Month",""&$B12) -> 9100 | E12: =IF(GETPIVOTDATA("Max of Num Month",Control!$A$3)>=$A12,C12,NA()) -> #N/A | F12: =IF(GETPIVOTDATA("Max of Num Month",Control!$A$3)<=$A12,C12,NA()) -> 14800 | G12: =IFERROR(GETPIVOTDATA(""&C$1,Control!$A$3,"Month",""&$B12),NA()) -> #N/A | H12: =IF(GETPIVOTDATA("Max of Num Month",Control!$A$3)>=$A12,C12,NA()) -> #N/A | I12: =IF(GETPIVOTDATA("Max of Num Month",Control!$A$3)>=$A12,D12,NA()) -> #N/A | J12: =IFERROR(GETPIVOTDATA(""&D$1,Control!$A$3,"Month",""&$B12),NA()) -> #N/A | L12: NOV | M12: =GETPIVOTDATA(""&M$1,Control!$A$20,"Month",""&$L12) -> 2500 | N12: =GETPIVOTDATA(""&N$1,Control!$A$20,"Month",""&$L12) -> 3920 | O12: =IFERROR(GETPIVOTDATA(""&N$1,Control!$A$3,"Month",""&$L12),NA()) -> #N/A | Q12: =GETPIVOTDATA("Average of Capital Velocity",Control!$A$3) -> 21.67 | R12: =50-Q12 -> 28.33 | S12: 35
A13: 12 | B13: DEC | C13: =GETPIVOTDATA(""&C$1,Control!$A$20,"Month",""&$B13) -> 18200 | D13: =GETPIVOTDATA(""&D$1,Control!$A$20,"Month",""&$B13) -> 12700 | E13: =IF(GETPIVOTDATA("Max of Num Month",Control!$A$3)>=$A13,C13,NA()) -> #N/A | F13: =IF(GETPIVOTDATA("Max of Num Month",Control!$A$3)<=$A13,C13,NA()) -> 18200 | G13: =IFERROR(GETPIVOTDATA(""&C$1,Control!$A$3,"Month",""&$B13),NA()) -> #N/A | H13: =IF(GETPIVOTDATA("Max of Num Month",Control!$A$3)>=$A13,C13,NA()) -> #N/A | I13: =IF(GETPIVOTDATA("Max of Num Month",Control!$A$3)>=$A13,D13,NA()) -> #N/A | J13: =IFERROR(GETPIVOTDATA(""&D$1,Control!$A$3,"Month",""&$B13),NA()) -> #N/A | L13: DEC | M13: =GETPIVOTDATA(""&M$1,Control!$A$20,"Month",""&$L13) -> 2700 | N13: =GETPIVOTDATA(""&N$1,Control!$A$20,"Month",""&$L13) -> 3200 | O13: =IFERROR(GETPIVOTDATA(""&N$1,Control!$A$3,"Month",""&$L13),NA()) -> #N/A | Q13: per productive hour
B14: Capital Growth Progress | G14: =GETPIVOTDATA("Sum of Planned",Control!$A$3) -> 19800 | J14: =GETPIVOTDATA("Sum of Actual",Control!$A$3) -> 13700 | L14: Income & Expenses | M14: =GETPIVOTDATA(""&M1,Control!$A$3) -> 5460 | N14: =GETPIVOTDATA(""&N1,Control!$A$3) -> 7840 | S14: https://exceltable.com/
A16: Income Sources | D16: Capital Allocation | H16: Sort | J16: Traffic Sources | M16: Leverages | N16: =ROUND(AVERAGE(N17:N24),2) -> 227.38 | P16: Wealth Engine Flywheel | R16: =GETPIVOTDATA("Max of Wealth Engine",Control!$A$3) -> 4 | U16: =(100%/6)*COUNTIF(U17:U22,"10") -> 0.66666667
A17: Salary | B17: =GETPIVOTDATA(""&A17,Control!$A$3) -> 1701 | D17: Investments | E17: =GETPIVOTDATA(""&D17,Control!$A$3) -> 3042 | G17: 38 | H17: {=_xlfn._xlws.SORT($J$17:$K$21,2,-1)} -> Blog Articles | I17: 20821 | J17: YouTube Videos | K17: =GETPIVOTDATA(""&J17,Control!$A$3) -> 17623 | M17: Automation | N17: =GETPIVOTDATA(""&M17,Control!$A$3) -> 214 | P17: Education | Q17: =IF($R$16>=$X17,$Q$23,"") -> • | R17: → | S17: =IF($R$16>$X17,R17,"") -> → | T17: =10-U17 -> 0 | U17: =IF($R$16>=$X17,10,0) -> 10 | V17: 0 | W17: =IF(T17,NA(),0) -> 0 | X17: 1
A18: Excel Templates | B18: =GETPIVOTDATA(""&A18,Control!$A$3) -> 1323 | D18: Cash Reserve | E18: =GETPIVOTDATA(""&D18,Control!$A$3) -> 3647 | G18: 24 | H18: Pinterest Pins | I18: 19294 | J18: Blog Articles | K18: =GETPIVOTDATA(""&J18,Control!$A$3) -> 20821 | M18: Copyability | N18: =GETPIVOTDATA(""&M18,Control!$A$3) -> 220 | P18: Creatie Assets | Q18: =IF($R$16>=$X18,$Q$23,"") -> • | R18: → | S18: =IF($R$16>$X18,R18,"") -> → | T18: =10-U18 -> 0 | U18: =IF($R$16>=$X18,10,0) -> 10 | V18: 0 | W18: =IF(T18,NA(),0) -> 0 | X18: 2
A19: YouTube | B19: =GETPIVOTDATA(""&A19,Control!$A$3) -> 1754 | D19: Digital Craft | E19: =GETPIVOTDATA(""&D19,Control!$A$3) -> 4271 | G19: 45 | H19: Instagram Reels | I19: 19130 | J19: Templates Etsy | K19: =GETPIVOTDATA(""&J19,Control!$A$3) -> 18780 | M19: Evergen | N19: =GETPIVOTDATA(""&M19,Control!$A$3) -> 167 | P19: Build Audience | Q19: =IF($R$16>=$X19,$Q$23,"") -> • | R19: → | S19: =IF($R$16>$X19,R19,"") -> → | T19: =10-U19 -> 0 | U19: =IF($R$16>=$X19,10,0) -> 10 | V19: 0 | W19: =IF(T19,NA(),0) -> 0 | X19: 3
A20: Affilate Marketing | B20: =GETPIVOTDATA(""&A20,Control!$A$3) -> 1495 | D20: Other Assets | E20: =GETPIVOTDATA(""&D20,Control!$A$3) -> 2740 | G20: 32 | H20: Templates Etsy | I20: 18780 | J20: Instagram Reels | K20: =GETPIVOTDATA(""&J20,Control!$A$3) -> 19130 | M20: Audience | N20: =GETPIVOTDATA(""&M20,Control!$A$3) -> 255 | P20: Get Income | Q20: =IF($R$16>=$X20,$Q$23,"") -> • | R20: → | S20: =IF($R$16>$X20,R20,"") | T20: =10-U20 -> 0 | U20: =IF($R$16>=$X20,10,0) -> 10 | V20: 0 | W20: =IF(T20,NA(),0) -> 0 | X20: 4
A21: Saving | B21: =GETPIVOTDATA(""&A21,Control!$A$3) -> 1567 | E21: =SUM(E17:E20) -> 13700 | G21: 152 | H21: YouTube Videos | I21: 17623 | J21: Pinterest Pins | K21: =GETPIVOTDATA(""&J21,Control!$A$3) -> 19294 | M21: Discoverability | N21: =GETPIVOTDATA(""&M21,Control!$A$3) -> 256 | P21: Invest & Growth | Q21: =IF($R$16>=$X21,$Q$23,"") | R21: → | S21: =IF($R$16>$X21,R21,"") | T21: =10-U21 -> 10 | U21: =IF($R$16>=$X21,10,0) -> 0 | V21: 0 | W21: =IF(T21,NA(),0) -> #N/A | X21: 5
B22: =SUM(B17:B21) -> 7840 | H22: Total | I22: =SUM(I17:I21) -> 95648 | M22: Conversion | N22: =GETPIVOTDATA(""&M22,Control!$A$3) -> 243 | P22: Build Capital | Q22: =IF($R$16>=$X22,$Q$23,"") | R22: → | S22: =IF($R$16>$X22,R22,"") | T22: =10-U22 -> 10 | U22: =IF($R$16>=$X22,10,0) -> 0 | V22: 0 | W22: =IF(T22,NA(),0) -> #N/A | X22: 6
M23: Scalability | N23: =GETPIVOTDATA(""&M23,Control!$A$3) -> 279 | Q23: •
M24: Independence | N24: =GETPIVOTDATA(""&M24,Control!$A$3) -> 185 | U24: =ISNUMBER(MATCH(U25,Control!$A$36:$A$38,0)) -> FALSE | V24: =ISNUMBER(MATCH(V25,Control!$A$36:$A$38,0)) -> TRUE | W24: =ISNUMBER(MATCH(W25,Control!$A$36:$A$38,0)) -> FALSE
A25: Low | B25: =S63-C25/2 -> 0.63666667 | C25: 0.06 | D25: =1.03-(S63+C25/2) -> 0.33333333 | U25: 2028 | V25: 2029 | W25: 2030
D26: =ISNUMBER(MATCH(D27,Control!$A$4:$A$15,0)) -> FALSE | E26: =ISNUMBER(MATCH(E27,Control!$A$4:$A$15,0)) -> FALSE | F26: =ISNUMBER(MATCH(F27,Control!$A$4:$A$15,0)) -> FALSE | G26: =ISNUMBER(MATCH(G27,Control!$A$4:$A$15,0)) -> TRUE | H26: =ISNUMBER(MATCH(H27,Control!$A$4:$A$15,0)) -> TRUE | I26: =ISNUMBER(MATCH(I27,Control!$A$4:$A$15,0)) -> TRUE | J26: =ISNUMBER(MATCH(J27,Control!$A$4:$A$15,0)) -> FALSE | K26: =ISNUMBER(MATCH(K27,Control!$A$4:$A$15,0)) -> FALSE | ... O26: =ISNUMBER(MATCH(O27,Control!$A$4:$A$15,0)) -> FALSE | Q26: Year | R26: Month | S26: Levels | U26: Scenario 1 | V26: Scenario 2 | W26: Scenario 3
A27: Heatmap Monthly Activity | D27: JAN | E27: FEB | F27: MAR | G27: APR | H27: MAY | I27: JUN | J27: JUL | K27: AUG | L27: SEP | M27: OCT | N27: NOV | O27: DEC | Q27: 2028 | R27: JAN | S27: =ROUND(AVERAGEIF(U27:W27,">0"),0) -> 1 | U27: =Data!AF2*U$24 -> 0 | V27: =Data!AG2*V$24 -> 1 | W27: =Data!AH2*W$24 -> 0
A28: =ISNUMBER(MATCH(C28,Control!$A$36:$A$38,0)) -> FALSE | B28: 1 | C28: 2028 | D28: {=(INDEX($S$27:$S$62,MATCH($C28&D$27,$Q$27:$Q$62&$R$27:$R$62,0))=$B28)*1} -> 1 | E28: {=(INDEX($S$27:$S$62,MATCH($C28&E$27,$Q$27:$Q$62&$R$27:$R$62,0))=$B28)*1} -> 1 | F28: {=(INDEX($S$27:$S$62,MATCH($C28&F$27,$Q$27:$Q$62&$R$27:$R$62,0))=$B28)*1} -> 1 | G28: {=(INDEX($S$27:$S$62,MATCH($C28&G$27,$Q$27:$Q$62&$R$27:$R$62,0))=$B28)*1} -> 1 | H28: {=(INDEX($S$27:$S$62,MATCH($C28&H$27,$Q$27:$Q$62&$R$27:$R$62,0))=$B28)*1} -> 0 | I28: {=(INDEX($S$27:$S$62,MATCH($C28&I$27,$Q$27:$Q$62&$R$27:$R$62,0))=$B28)*1} -> 1 | J28: {=(INDEX($S$27:$S$62,MATCH($C28&J$27,$Q$27:$Q$62&$R$27:$R$62,0))=$B28)*1} -> 1 | K28: {=(INDEX($S$27:$S$62,MATCH($C28&K$27,$Q$27:$Q$62&$R$27:$R$62,0))=$B28)*1} -> 0 | ... O28: {=(INDEX($S$27:$S$62,MATCH($C28&O$27,$Q$27:$Q$62&$R$27:$R$62,0))=$B28)*1} -> 0 | Q28: 2028 | R28: FEB | S28: =ROUND(AVERAGEIF(U28:W28,">0"),0) -> 1 | U28: =Data!AF3*U$24 -> 0 | V28: =Data!AG3*V$24 -> 1 | W28: =Data!AH3*W$24 -> 0
A29: =ISNUMBER(MATCH(C29,Control!$A$36:$A$38,0)) -> FALSE | B29: 2 | C29: 2028 | D29: {=(INDEX($S$27:$S$62,MATCH($C29&D$27,$Q$27:$Q$62&$R$27:$R$62,0))=$B29)*1} -> 0 | E29: {=(INDEX($S$27:$S$62,MATCH($C29&E$27,$Q$27:$Q$62&$R$27:$R$62,0))=$B29)*1} -> 0 | F29: {=(INDEX($S$27:$S$62,MATCH($C29&F$27,$Q$27:$Q$62&$R$27:$R$62,0))=$B29)*1} -> 0 | G29: {=(INDEX($S$27:$S$62,MATCH($C29&G$27,$Q$27:$Q$62&$R$27:$R$62,0))=$B29)*1} -> 0 | H29: {=(INDEX($S$27:$S$62,MATCH($C29&H$27,$Q$27:$Q$62&$R$27:$R$62,0))=$B29)*1} -> 0 | I29: {=(INDEX($S$27:$S$62,MATCH($C29&I$27,$Q$27:$Q$62&$R$27:$R$62,0))=$B29)*1} -> 0 | J29: {=(INDEX($S$27:$S$62,MATCH($C29&J$27,$Q$27:$Q$62&$R$27:$R$62,0))=$B29)*1} -> 0 | K29: {=(INDEX($S$27:$S$62,MATCH($C29&K$27,$Q$27:$Q$62&$R$27:$R$62,0))=$B29)*1} -> 0 | ... O29: {=(INDEX($S$27:$S$62,MATCH($C29&O$27,$Q$27:$Q$62&$R$27:$R$62,0))=$B29)*1} -> 1 | Q29: 2028 | R29: MAR | S29: =ROUND(AVERAGEIF(U29:W29,">0"),0) -> 1 | U29: =Data!AF4*U$24 -> 0 | V29: =Data!AG4*V$24 -> 1 | W29: =Data!AH4*W$24 -> 0
A30: =ISNUMBER(MATCH(C30,Control!$A$36:$A$38,0)) -> FALSE | B30: 3 | C30: 2028 | D30: {=(INDEX($S$27:$S$62,MATCH($C30&D$27,$Q$27:$Q$62&$R$27:$R$62,0))=$B30)*1} -> 0 | E30: {=(INDEX($S$27:$S$62,MATCH($C30&E$27,$Q$27:$Q$62&$R$27:$R$62,0))=$B30)*1} -> 0 | F30: {=(INDEX($S$27:$S$62,MATCH($C30&F$27,$Q$27:$Q$62&$R$27:$R$62,0))=$B30)*1} -> 0 | G30: {=(INDEX($S$27:$S$62,MATCH($C30&G$27,$Q$27:$Q$62&$R$27:$R$62,0))=$B30)*1} -> 0 | H30: {=(INDEX($S$27:$S$62,MATCH($C30&H$27,$Q$27:$Q$62&$R$27:$R$62,0))=$B30)*1} -> 1 | I30: {=(INDEX($S$27:$S$62,MATCH($C30&I$27,$Q$27:$Q$62&$R$27:$R$62,0))=$B30)*1} -> 0 | J30: {=(INDEX($S$27:$S$62,MATCH($C30&J$27,$Q$27:$Q$62&$R$27:$R$62,0))=$B30)*1} -> 0 | K30: {=(INDEX($S$27:$S$62,MATCH($C30&K$27,$Q$27:$Q$62&$R$27:$R$62,0))=$B30)*1} -> 1 | ... O30: {=(INDEX($S$27:$S$62,MATCH($C30&O$27,$Q$27:$Q$62&$R$27:$R$62,0))=$B30)*1} -> 0 | Q30: 2028 | R30: APR | S30: =ROUND(AVERAGEIF(U30:W30,">0"),0) -> 1 | U30: =Data!AF5*U$24 -> 0 | V30: =Data!AG5*V$24 -> 1 | W30: =Data!AH5*W$24 -> 0
A31: =ISNUMBER(MATCH(C31,Control!$A$36:$A$38,0)) -> FALSE | B31: 4 | C31: 2028 | D31: {=(INDEX($S$27:$S$62,MATCH($C31&D$27,$Q$27:$Q$62&$R$27:$R$62,0))=$B31)*1} -> 0 | E31: {=(INDEX($S$27:$S$62,MATCH($C31&E$27,$Q$27:$Q$62&$R$27:$R$62,0))=$B31)*1} -> 0 | F31: {=(INDEX($S$27:$S$62,MATCH($C31&F$27,$Q$27:$Q$62&$R$27:$R$62,0))=$B31)*1} -> 0 | G31: {=(INDEX($S$27:$S$62,MATCH($C31&G$27,$Q$27:$Q$62&$R$27:$R$62,0))=$B31)*1} -> 0 | H31: {=(INDEX($S$27:$S$62,MATCH($C31&H$27,$Q$27:$Q$62&$R$27:$R$62,0))=$B31)*1} -> 0 | I31: {=(INDEX($S$27:$S$62,MATCH($C31&I$27,$Q$27:$Q$62&$R$27:$R$62,0))=$B31)*1} -> 0 | J31: {=(INDEX($S$27:$S$62,MATCH($C31&J$27,$Q$27:$Q$62&$R$27:$R$62,0))=$B31)*1} -> 0 | K31: {=(INDEX($S$27:$S$62,MATCH($C31&K$27,$Q$27:$Q$62&$R$27:$R$62,0))=$B31)*1} -> 0 | ... O31: {=(INDEX($S$27:$S$62,MATCH($C31&O$27,$Q$27:$Q$62&$R$27:$R$62,0))=$B31)*1} -> 0 | Q31: 2028 | R31: MAY | S31: =ROUND(AVERAGEIF(U31:W31,">0"),0) -> 3 | U31: =Data!AF6*U$24 -> 0 | V31: =Data!AG6*V$24 -> 3 | W31: =Data!AH6*W$24 -> 0
A32: =ISNUMBER(MATCH(C32,Control!$A$36:$A$38,0)) -> TRUE | B32: 1 | C32: 2029 | D32: {=(INDEX($S$27:$S$62,MATCH($C32&D$27,$Q$27:$Q$62&$R$27:$R$62,0))=$B32)*1} -> 1 | E32: {=(INDEX($S$27:$S$62,MATCH($C32&E$27,$Q$27:$Q$62&$R$27:$R$62,0))=$B32)*1} -> 1 | F32: {=(INDEX($S$27:$S$62,MATCH($C32&F$27,$Q$27:$Q$62&$R$27:$R$62,0))=$B32)*1} -> 0 | G32: {=(INDEX($S$27:$S$62,MATCH($C32&G$27,$Q$27:$Q$62&$R$27:$R$62,0))=$B32)*1} -> 0 | H32: {=(INDEX($S$27:$S$62,MATCH($C32&H$27,$Q$27:$Q$62&$R$27:$R$62,0))=$B32)*1} -> 0 | I32: {=(INDEX($S$27:$S$62,MATCH($C32&I$27,$Q$27:$Q$62&$R$27:$R$62,0))=$B32)*1} -> 1 | J32: {=(INDEX($S$27:$S$62,MATCH($C32&J$27,$Q$27:$Q$62&$R$27:$R$62,0))=$B32)*1} -> 1 | K32: {=(INDEX($S$27:$S$62,MATCH($C32&K$27,$Q$27:$Q$62&$R$27:$R$62,0))=$B32)*1} -> 0 | ... O32: {=(INDEX($S$27:$S$62,MATCH($C32&O$27,$Q$27:$Q$62&$R$27:$R$62,0))=$B32)*1} -> 0 | Q32: 2028 | R32: JUN | S32: =ROUND(AVERAGEIF(U32:W32,">0"),0) -> 1 | U32: =Data!AF7*U$24 -> 0 | V32: =Data!AG7*V$24 -> 1 | W32: =Data!AH7*W$24 -> 0
A33: =ISNUMBER(MATCH(C33,Control!$A$36:$A$38,0)) -> TRUE | B33: 2 | C33: 2029 | D33: {=(INDEX($S$27:$S$62,MATCH($C33&D$27,$Q$27:$Q$62&$R$27:$R$62,0))=$B33)*1} -> 0 | E33: {=(INDEX($S$27:$S$62,MATCH($C33&E$27,$Q$27:$Q$62&$R$27:$R$62,0))=$B33)*1} -> 0 | F33: {=(INDEX($S$27:$S$62,MATCH($C33&F$27,$Q$27:$Q$62&$R$27:$R$62,0))=$B33)*1} -> 1 | G33: {=(INDEX($S$27:$S$62,MATCH($C33&G$27,$Q$27:$Q$62&$R$27:$R$62,0))=$B33)*1} -> 0 | H33: {=(INDEX($S$27:$S$62,MATCH($C33&H$27,$Q$27:$Q$62&$R$27:$R$62,0))=$B33)*1} -> 0 | I33: {=(INDEX($S$27:$S$62,MATCH($C33&I$27,$Q$27:$Q$62&$R$27:$R$62,0))=$B33)*1} -> 0 | J33: {=(INDEX($S$27:$S$62,MATCH($C33&J$27,$Q$27:$Q$62&$R$27:$R$62,0))=$B33)*1} -> 0 | K33: {=(INDEX($S$27:$S$62,MATCH($C33&K$27,$Q$27:$Q$62&$R$27:$R$62,0))=$B33)*1} -> 0 | ... O33: {=(INDEX($S$27:$S$62,MATCH($C33&O$27,$Q$27:$Q$62&$R$27:$R$62,0))=$B33)*1} -> 1 | Q33: 2028 | R33: JUL | S33: =ROUND(AVERAGEIF(U33:W33,">0"),0) -> 1 | U33: =Data!AF8*U$24 -> 0 | V33: =Data!AG8*V$24 -> 1 | W33: =Data!AH8*W$24 -> 0
A34: =ISNUMBER(MATCH(C34,Control!$A$36:$A$38,0)) -> TRUE | B34: 3 | C34: 2029 | D34: {=(INDEX($S$27:$S$62,MATCH($C34&D$27,$Q$27:$Q$62&$R$27:$R$62,0))=$B34)*1} -> 0 | E34: {=(INDEX($S$27:$S$62,MATCH($C34&E$27,$Q$27:$Q$62&$R$27:$R$62,0))=$B34)*1} -> 0 | F34: {=(INDEX($S$27:$S$62,MATCH($C34&F$27,$Q$27:$Q$62&$R$27:$R$62,0))=$B34)*1} -> 0 | G34: {=(INDEX($S$27:$S$62,MATCH($C34&G$27,$Q$27:$Q$62&$R$27:$R$62,0))=$B34)*1} -> 1 | H34: {=(INDEX($S$27:$S$62,MATCH($C34&H$27,$Q$27:$Q$62&$R$27:$R$62,0))=$B34)*1} -> 0 | I34: {=(INDEX($S$27:$S$62,MATCH($C34&I$27,$Q$27:$Q$62&$R$27:$R$62,0))=$B34)*1} -> 0 | J34: {=(INDEX($S$27:$S$62,MATCH($C34&J$27,$Q$27:$Q$62&$R$27:$R$62,0))=$B34)*1} -> 0 | K34: {=(INDEX($S$27:$S$62,MATCH($C34&K$27,$Q$27:$Q$62&$R$27:$R$62,0))=$B34)*1} -> 1 | ... O34: {=(INDEX($S$27:$S$62,MATCH($C34&O$27,$Q$27:$Q$62&$R$27:$R$62,0))=$B34)*1} -> 0 | Q34: 2028 | R34: AUG | S34: =ROUND(AVERAGEIF(U34:W34,">0"),0) -> 3 | U34: =Data!AF9*U$24 -> 0 | V34: =Data!AG9*V$24 -> 3 | W34: =Data!AH9*W$24 -> 0
A35: =ISNUMBER(MATCH(C35,Control!$A$36:$A$38,0)) -> TRUE | B35: 4 | C35: 2029 | D35: {=(INDEX($S$27:$S$62,MATCH($C35&D$27,$Q$27:$Q$62&$R$27:$R$62,0))=$B35)*1} -> 0 | E35: {=(INDEX($S$27:$S$62,MATCH($C35&E$27,$Q$27:$Q$62&$R$27:$R$62,0))=$B35)*1} -> 0 | F35: {=(INDEX($S$27:$S$62,MATCH($C35&F$27,$Q$27:$Q$62&$R$27:$R$62,0))=$B35)*1} -> 0 | G35: {=(INDEX($S$27:$S$62,MATCH($C35&G$27,$Q$27:$Q$62&$R$27:$R$62,0))=$B35)*1} -> 0 | H35: {=(INDEX($S$27:$S$62,MATCH($C35&H$27,$Q$27:$Q$62&$R$27:$R$62,0))=$B35)*1} -> 1 | I35: {=(INDEX($S$27:$S$62,MATCH($C35&I$27,$Q$27:$Q$62&$R$27:$R$62,0))=$B35)*1} -> 0 | J35: {=(INDEX($S$27:$S$62,MATCH($C35&J$27,$Q$27:$Q$62&$R$27:$R$62,0))=$B35)*1} -> 0 | K35: {=(INDEX($S$27:$S$62,MATCH($C35&K$27,$Q$27:$Q$62&$R$27:$R$62,0))=$B35)*1} -> 0 | ... O35: {=(INDEX($S$27:$S$62,MATCH($C35&O$27,$Q$27:$Q$62&$R$27:$R$62,0))=$B35)*1} -> 0 | Q35: 2028 | R35: SEP | S35: =ROUND(AVERAGEIF(U35:W35,">0"),0) -> 1 | U35: =Data!AF10*U$24 -> 0 | V35: =Data!AG10*V$24 -> 1 | W35: =Data!AH10*W$24 -> 0
A36: =ISNUMBER(MATCH(C36,Control!$A$36:$A$38,0)) -> FALSE | B36: 1 | C36: 2030 | D36: {=(INDEX($S$27:$S$62,MATCH($C36&D$27,$Q$27:$Q$62&$R$27:$R$62,0))=$B36)*1} -> 1 | E36: {=(INDEX($S$27:$S$62,MATCH($C36&E$27,$Q$27:$Q$62&$R$27:$R$62,0))=$B36)*1} -> 0 | F36: {=(INDEX($S$27:$S$62,MATCH($C36&F$27,$Q$27:$Q$62&$R$27:$R$62,0))=$B36)*1} -> 1 | G36: {=(INDEX($S$27:$S$62,MATCH($C36&G$27,$Q$27:$Q$62&$R$27:$R$62,0))=$B36)*1} -> 1 | H36: {=(INDEX($S$27:$S$62,MATCH($C36&H$27,$Q$27:$Q$62&$R$27:$R$62,0))=$B36)*1} -> 0 | I36: {=(INDEX($S$27:$S$62,MATCH($C36&I$27,$Q$27:$Q$62&$R$27:$R$62,0))=$B36)*1} -> 0 | J36: {=(INDEX($S$27:$S$62,MATCH($C36&J$27,$Q$27:$Q$62&$R$27:$R$62,0))=$B36)*1} -> 0 | K36: {=(INDEX($S$27:$S$62,MATCH($C36&K$27,$Q$27:$Q$62&$R$27:$R$62,0))=$B36)*1} -> 1 | ... O36: {=(INDEX($S$27:$S$62,MATCH($C36&O$27,$Q$27:$Q$62&$R$27:$R$62,0))=$B36)*1} -> 1 | Q36: 2028 | R36: OCT | S36: =ROUND(AVERAGEIF(U36:W36,">0"),0) -> 1 | U36: =Data!AF11*U$24 -> 0 | V36: =Data!AG11*V$24 -> 1 | W36: =Data!AH11*W$24 -> 0
A37: =ISNUMBER(MATCH(C37,Control!$A$36:$A$38,0)) -> FALSE | B37: 2 | C37: 2030 | D37: {=(INDEX($S$27:$S$62,MATCH($C37&D$27,$Q$27:$Q$62&$R$27:$R$62,0))=$B37)*1} -> 0 | E37: {=(INDEX($S$27:$S$62,MATCH($C37&E$27,$Q$27:$Q$62&$R$27:$R$62,0))=$B37)*1} -> 1 | F37: {=(INDEX($S$27:$S$62,MATCH($C37&F$27,$Q$27:$Q$62&$R$27:$R$62,0))=$B37)*1} -> 0 | G37: {=(INDEX($S$27:$S$62,MATCH($C37&G$27,$Q$27:$Q$62&$R$27:$R$62,0))=$B37)*1} -> 0 | H37: {=(INDEX($S$27:$S$62,MATCH($C37&H$27,$Q$27:$Q$62&$R$27:$R$62,0))=$B37)*1} -> 0 | I37: {=(INDEX($S$27:$S$62,MATCH($C37&I$27,$Q$27:$Q$62&$R$27:$R$62,0))=$B37)*1} -> 0 | J37: {=(INDEX($S$27:$S$62,MATCH($C37&J$27,$Q$27:$Q$62&$R$27:$R$62,0))=$B37)*1} -> 1 | K37: {=(INDEX($S$27:$S$62,MATCH($C37&K$27,$Q$27:$Q$62&$R$27:$R$62,0))=$B37)*1} -> 0 | ... O37: {=(INDEX($S$27:$S$62,MATCH($C37&O$27,$Q$27:$Q$62&$R$27:$R$62,0))=$B37)*1} -> 0 | Q37: 2028 | R37: NOV | S37: =ROUND(AVERAGEIF(U37:W37,">0"),0) -> 2 | U37: =Data!AF12*U$24 -> 0 | V37: =Data!AG12*V$24 -> 2 | W37: =Data!AH12*W$24 -> 0
A38: =ISNUMBER(MATCH(C38,Control!$A$36:$A$38,0)) -> FALSE | B38: 3 | C38: 2030 | D38: {=(INDEX($S$27:$S$62,MATCH($C38&D$27,$Q$27:$Q$62&$R$27:$R$62,0))=$B38)*1} -> 0 | E38: {=(INDEX($S$27:$S$62,MATCH($C38&E$27,$Q$27:$Q$62&$R$27:$R$62,0))=$B38)*1} -> 0 | F38: {=(INDEX($S$27:$S$62,MATCH($C38&F$27,$Q$27:$Q$62&$R$27:$R$62,0))=$B38)*1} -> 0 | G38: {=(INDEX($S$27:$S$62,MATCH($C38&G$27,$Q$27:$Q$62&$R$27:$R$62,0))=$B38)*1} -> 0 | H38: {=(INDEX($S$27:$S$62,MATCH($C38&H$27,$Q$27:$Q$62&$R$27:$R$62,0))=$B38)*1} -> 0 | I38: {=(INDEX($S$27:$S$62,MATCH($C38&I$27,$Q$27:$Q$62&$R$27:$R$62,0))=$B38)*1} -> 0 | J38: {=(INDEX($S$27:$S$62,MATCH($C38&J$27,$Q$27:$Q$62&$R$27:$R$62,0))=$B38)*1} -> 0 | K38: {=(INDEX($S$27:$S$62,MATCH($C38&K$27,$Q$27:$Q$62&$R$27:$R$62,0))=$B38)*1} -> 0 | ... O38: {=(INDEX($S$27:$S$62,MATCH($C38&O$27,$Q$27:$Q$62&$R$27:$R$62,0))=$B38)*1} -> 0 | Q38: 2028 | R38: DEC | S38: =ROUND(AVERAGEIF(U38:W38,">0"),0) -> 2 | U38: =Data!AF13*U$24 -> 0 | V38: =Data!AG13*V$24 -> 2 | W38: =Data!AH13*W$24 -> 0
A39: =ISNUMBER(MATCH(C39,Control!$A$36:$A$38,0)) -> FALSE | B39: 4 | C39: 2030 | D39: {=(INDEX($S$27:$S$62,MATCH($C39&D$27,$Q$27:$Q$62&$R$27:$R$62,0))=$B39)*1} -> 0 | E39: {=(INDEX($S$27:$S$62,MATCH($C39&E$27,$Q$27:$Q$62&$R$27:$R$62,0))=$B39)*1} -> 0 | F39: {=(INDEX($S$27:$S$62,MATCH($C39&F$27,$Q$27:$Q$62&$R$27:$R$62,0))=$B39)*1} -> 0 | G39: {=(INDEX($S$27:$S$62,MATCH($C39&G$27,$Q$27:$Q$62&$R$27:$R$62,0))=$B39)*1} -> 0 | H39: {=(INDEX($S$27:$S$62,MATCH($C39&H$27,$Q$27:$Q$62&$R$27:$R$62,0))=$B39)*1} -> 1 | I39: {=(INDEX($S$27:$S$62,MATCH($C39&I$27,$Q$27:$Q$62&$R$27:$R$62,0))=$B39)*1} -> 1 | J39: {=(INDEX($S$27:$S$62,MATCH($C39&J$27,$Q$27:$Q$62&$R$27:$R$62,0))=$B39)*1} -> 0 | K39: {=(INDEX($S$27:$S$62,MATCH($C39&K$27,$Q$27:$Q$62&$R$27:$R$62,0))=$B39)*1} -> 0 | ... O39: {=(INDEX($S$27:$S$62,MATCH($C39&O$27,$Q$27:$Q$62&$R$27:$R$62,0))=$B39)*1} -> 0 | Q39: 2029 | R39: JAN | S39: =ROUND(AVERAGEIF(U39:W39,">0"),0) -> 1 | U39: =Data!AF14*U$24 -> 0 | V39: =Data!AG14*V$24 -> 1 | W39: =Data!AH14*W$24 -> 0
A40: =ISNUMBER(MATCH(C40,Control!$A$36:$A$38,0)) -> FALSE | B40: Off | C40: 2028 | D40: =NOT(AND($A40,D$26))*1 -> 1 | E40: =NOT(AND($A40,E$26))*1 -> 1 | F40: =NOT(AND($A40,F$26))*1 -> 1 | G40: =NOT(AND($A40,G$26))*1 -> 1 | H40: =NOT(AND($A40,H$26))*1 -> 1 | I40: =NOT(AND($A40,I$26))*1 -> 1 | J40: =NOT(AND($A40,J$26))*1 -> 1 | K40: =NOT(AND($A40,K$26))*1 -> 1 | ... O40: =NOT(AND($A40,O$26))*1 -> 1 | Q40: 2029 | R40: FEB | S40: =ROUND(AVERAGEIF(U40:W40,">0"),0) -> 1 | U40: =Data!AF15*U$24 -> 0 | V40: =Data!AG15*V$24 -> 1 | W40: =Data!AH15*W$24 -> 0
A41: =ISNUMBER(MATCH(C41,Control!$A$36:$A$38,0)) -> FALSE | B41: On | C41: 2028 | D41: =$A41*D$26 -> 0 | E41: =$A41*E$26 -> 0 | F41: =$A41*F$26 -> 0 | G41: =$A41*G$26 -> 0 | H41: =$A41*H$26 -> 0 | I41: =$A41*I$26 -> 0 | J41: =$A41*J$26 -> 0 | K41: =$A41*K$26 -> 0 | ... O41: =$A41*O$26 -> 0 | Q41: 2029 | R41: MAR | S41: =ROUND(AVERAGEIF(U41:W41,">0"),0) -> 2 | U41: =Data!AF16*U$24 -> 0 | V41: =Data!AG16*V$24 -> 2 | W41: =Data!AH16*W$24 -> 0
...

Sheet Control
A1: https://exceltable.com/
A3: Row Labels | B3: Max of Count | C3: Max of Num Month | D3: Sum of Expenses | E3: Sum of Income | F3: Sum of Planned | G3: Sum of Actual | H3: Sum of Salary | I3: Sum of Excel Templates | J3: Sum of YouTube | K3: Sum of Affilate Marketing | L3: Sum of Saving | M3: Sum of Investments | N3: Sum of Cash Reserve | O3: Sum of Digital Craft | P3: Sum of Other Assets | Q3: Sum of YouTube Videos | R3: Sum of Blog Articles | S3: Sum of Templates Etsy | T3: Sum of Instagram Reels | U3: Sum of Pinterest Pins | V3: Sum of Automation | W3: Sum of Copyability | X3: Sum of Evergen | Y3: Sum of Audience | Z3: Sum of Discoverability | AA3: Sum of Conversion | AB3: Sum of Scalability | AC3: Sum of Independence | AD3: Max of Wealth Engine | AE3: Average of Capital Velocity
A4: APR | B4: 16 | C4: 4 | D4: 2100 | E4: 1800 | F4: 5800 | G4: 4300 | H4: 308 | I4: 337 | J4: 383 | K4: 412 | L4: 360 | M4: 1316 | N4: 1167 | O4: 957 | P4: 860 | Q4: 4146 | R4: 4708 | S4: 3514 | T4: 4392 | U4: 5200 | V4: 95 | W4: 64 | X4: 42 | Y4: 99 | Z4: 84 | AA4: 49 | AB4: 88 | AC4: 72 | AD4: 4 | AE4: 21.85
A5: MAY | B5: 17 | C5: 5 | D5: 1660 | E5: 2800 | F5: 6300 | G5: 4000 | H5: 779 | I5: 416 | J5: 779 | K5: 267 | L5: 559 | M5: 800 | N5: 1006 | O5: 1394 | P5: 800 | Q5: 6265 | R5: 7237 | S5: 7129 | T5: 6832 | U5: 6697 | V5: 43 | W5: 82 | X5: 70 | Y5: 100 | Z5: 91 | AA5: 98 | AB5: 97 | AC5: 70 | AD5: 4 | AE5: 21.45
A6: JUN | B6: 18 | C6: 6 | D6: 1700 | E6: 3240 | F6: 7700 | G6: 5400 | H6: 614 | I6: 570 | J6: 592 | K6: 816 | L6: 648 | M6: 926 | N6: 1474 | O6: 1920 | P6: 1080 | Q6: 7212 | R6: 8876 | S6: 8137 | T6: 7906 | U6: 7397 | V6: 76 | W6: 74 | X6: 55 | Y6: 56 | Z6: 81 | AA6: 96 | AB6: 94 | AC6: 43 | AD6: 4 | AE6: 21.71
A7: Grand Total | B7: 18 | C7: 6 | D7: 5460 | E7: 7840 | F7: 19800 | G7: 13700 | H7: 1701 | I7: 1323 | J7: 1754 | K7: 1495 | L7: 1567 | M7: 3042 | N7: 3647 | O7: 4271 | P7: 2740 | Q7: 17623 | R7: 20821 | S7: 18780 | T7: 19130 | U7: 19294 | V7: 214 | W7: 220 | X7: 167 | Y7: 255 | Z7: 256 | AA7: 243 | AB7: 279 | AC7: 185 | AD7: 4 | AE7: 21.67
A20: Row Labels | B20: Sum of Expenses | C20: Sum of Income | D20: Sum of Planned | E20: Sum of Actual
A21: JAN | B21: 2300 | C21: 2000 | D21: 3800 | E21: 2700
A22: FEB | B22: 2700 | C22: 1600 | D22: 4100 | E22: 2950
A23: MAR | B23: 2620 | C23: 1400 | D23: 5100 | E23: 3600
A24: APR | B24: 2100 | C24: 1800 | D24: 5800 | E24: 4300
A25: MAY | B25: 1660 | C25: 2800 | D25: 6300 | E25: 4000
A26: JUN | B26: 1700 | C26: 3240 | D26: 7700 | E26: 5400
A27: JUL | B27: 2300 | C27: 3200 | D27: 8900 | E27: 6300
A28: AUG | B28: 3020 | C28: 3000 | D28: 9600 | E28: 5900
A29: SEP | B29: 3180 | C29: 3200 | D29: 11900 | E29: 8100
A30: OCT | B30: 2700 | C30: 4000 | D30: 13700 | E30: 9600
A31: NOV | B31: 2500 | C31: 3920 | D31: 14800 | E31: 9100
A32: DEC | B32: 2700 | C32: 3200 | D32: 18200 | E32: 12700
A33: Grand Total | B33: 29480 | C33: 33360 | D33: 109900 | E33: 74650
A35: Row Labels | B35: Max of Scenarios
A36: 2029 | B36: 2
A37: Grand Total | B37: 2

Sheet Data
A1: Year | B1: Month | C1: Num Month | D1: Count | E1: Expenses | F1: Income | G1: Planned | H1: Actual | I1: Salary | J1: Excel Templates | K1: YouTube | L1: Affilate Marketing | M1: Saving | N1: Investments | O1: Cash Reserve | P1: Digital Craft | Q1: Other Assets | R1: YouTube Videos | S1: Blog Articles | T1: Templates Etsy | U1: Instagram Reels | V1: Pinterest Pins | W1: Automation | X1: Copyability | Y1: Evergen | Z1: Audience | AA1: Discoverability | AB1: Conversion | AC1: Scalability | AD1: Independence | AE1: Wealth Engine | AF1: Scenario 1 | AG1: Scenario 2 | AH1: Scenario 3 | AI1: Scenarios | AJ1: Capital Velocity | AL1: https://exceltable.com/
A2: 2028 | B2: JAN | C2: 1 | D2: 1 | E2: 2001 | F2: 3200 | G2: 1000 | H2: 1000 | I2: 667 | J2: 796 | K2: 538 | L2: 559 | M2: 640 | N2: 244 | O2: 249 | P2: 306 | Q2: 201 | R2: 8566 | S2: 9356 | T2: 5798 | U2: 7809 | V2: 7511 | W2: 45 | X2: 93 | Y2: 80 | Z2: 54 | AA2: 72 | AB2: 92 | AC2: 89 | AD2: 42 | AE2: 1 | AF2: 1 | AG2: 1 | AH2: 3 | AI2: 1 | AJ2: 8.51
A3: 2028 | B3: FEB | C3: 2 | D3: 2 | E3: 1601 | F3: 2552 | G3: 1200 | H3: 900 | I3: 464 | J3: 384 | K3: 636 | L3: 557 | M3: 511 | N3: 230 | O3: 259 | P3: 230 | Q3: 181 | R3: 6887 | S3: 5739 | T3: 6772 | U3: 6227 | V3: 5509 | W3: 61 | X3: 60 | Y3: 81 | Z3: 85 | AA3: 63 | AB3: 55 | AC3: 59 | AD3: 73 | AE3: 1 | AF3: 1 | AG3: 1 | AH3: 4 | AI3: 1 | AJ3: 8.36
A4: 2028 | B4: MAR | C4: 3 | D4: 3 | E4: 1401 | F4: 2108 | G4: 1150 | H4: 1020 | I4: 387 | J4: 460 | K4: 589 | L4: 250 | M4: 422 | N4: 295 | O4: 267 | P4: 253 | Q4: 205 | R4: 6237 | S4: 4748 | T4: 3165 | U4: 5144 | V4: 6424 | W4: 68 | X4: 99 | Y4: 72 | Z4: 83 | AA4: 50 | AB4: 91 | AC4: 100 | AD4: 78 | AE4: 1 | AF4: 1 | AG4: 1 | AH4: 1 | AI4: 1 | AJ4: 8.39
A5: 2028 | B5: APR | C5: 4 | D5: 4 | E5: 1801 | F5: 2012 | G5: 1520 | H5: 1350 | I5: 454 | J5: 385 | K5: 341 | L5: 429 | M5: 403 | N5: 388 | O5: 377 | P5: 316 | Q5: 269 | R5: 5397 | S5: 4823 | T5: 3675 | U5: 4909 | V5: 5742 | W5: 44 | X5: 76 | Y5: 45 | Z5: 98 | AA5: 87 | AB5: 54 | AC5: 83 | AD5: 66 | AE5: 2 | AF5: 2 | AG5: 1 | AH5: 2 | AI5: 1 | AJ5: 13.79
A6: 2028 | B6: MAY | C6: 5 | D6: 5 | E6: 2801 | F6: 2292 | G6: 1770 | H6: 1210 | I6: 662 | J6: 499 | K6: 298 | L6: 374 | M6: 459 | N6: 327 | O6: 216 | P6: 425 | Q6: 242 | R6: 6668 | S6: 5807 | T6: 4087 | U6: 5593 | V6: 5807 | W6: 69 | X6: 84 | Y6: 89 | Z6: 46 | AA6: 47 | AB6: 85 | AC6: 42 | AD6: 46 | AE6: 2 | AF6: 1 | AG6: 3 | AH6: 1 | AI6: 1 | AJ6: 13.52
A7: 2028 | B7: JUN | C7: 6 | D7: 6 | E7: 3240 | F7: 2860 | G7: 1810 | H7: 1505 | I7: 680 | J7: 773 | K7: 484 | L7: 350 | M7: 573 | N7: 503 | O7: 351 | P7: 351 | Q7: 300 | R7: 5583 | S7: 4399 | T7: 11165 | U7: 6978 | V7: 6767 | W7: 73 | X7: 71 | Y7: 91 | Z7: 45 | AA7: 95 | AB7: 77 | AC7: 84 | AD7: 82 | AE7: 2 | AF7: 3 | AG7: 1 | AH7: 1 | AI7: 1 | AJ7: 13.11
A8: 2028 | B8: JUL | C8: 7 | D8: 7 | E8: 3201 | F8: 3540 | G8: 2275 | H8: 1710 | I8: 446 | J8: 774 | K8: 905 | L8: 708 | M8: 707 | N8: 374 | O8: 315 | P8: 679 | Q8: 342 | R8: 13668 | S8: 5315 | T8: 6454 | U8: 8639 | V8: 9112 | W8: 93 | X8: 66 | Y8: 61 | Z8: 53 | AA8: 49 | AB8: 48 | AC8: 66 | AD8: 76 | AE8: 2 | AF8: 1 | AG8: 1 | AH8: 2 | AI8: 1 | AJ8: 13.7
A9: 2028 | B9: AUG | C9: 8 | D9: 8 | E9: 3001 | F9: 4108 | G9: 2402 | H9: 1670 | I9: 975 | J9: 696 | K9: 919 | L9: 696 | M9: 822 | N9: 507 | O9: 295 | P9: 534 | Q9: 334 | R9: 7329 | S9: 14011 | T9: 11856 | U9: 10024 | V9: 6898 | W9: 75 | X9: 40 | Y9: 75 | Z9: 94 | AA9: 83 | AB9: 54 | AC9: 100 | AD9: 54 | AE9: 2 | AF9: 2 | AG9: 3 | AH9: 3 | AI9: 1 | AJ9: 13.55
A10: 2028 | B10: SEP | C10: 9 | D10: 9 | E10: 3200 | F10: 4388 | G10: 2570 | H10: 1950 | I10: 670 | J10: 954 | K10: 1136 | L10: 751 | M10: 877 | N10: 464 | O10: 438 | P10: 658 | Q10: 390 | R10: 5447 | S10: 13712 | T10: 13900 | U10: 10707 | V10: 9768 | W10: 53 | X10: 85 | Y10: 61 | Z10: 77 | AA10: 61 | AB10: 77 | AC10: 92 | AD10: 99 | AE10: 3 | AF10: 1 | AG10: 1 | AH10: 2 | AI10: 1 | AJ10: 18.88
A11: 2028 | B11: OCT | C11: 10 | D11: 10 | E11: 4001 | F11: 4292 | G11: 2490 | H11: 2120 | I11: 1097 | J11: 496 | K11: 938 | L11: 903 | M11: 858 | N11: 834 | O11: 460 | P11: 402 | Q11: 424 | R11: 7207 | S11: 11486 | T11: 9009 | U11: 10472 | V11: 14188 | W11: 41 | X11: 78 | Y11: 82 | Z11: 100 | AA11: 53 | AB11: 68 | AC11: 45 | AD11: 83 | AE11: 3 | AF11: 2 | AG11: 1 | AH11: 2 | AI11: 1 | AJ11: 18.32
A12: 2028 | B12: NOV | C12: 11 | D12: 11 | E12: 3921 | F12: 3848 | G12: 2760 | H12: 2050 | I12: 480 | J12: 1031 | K12: 607 | L12: 960 | M12: 770 | N12: 436 | O12: 423 | P12: 780 | Q12: 411 | R12: 5557 | S12: 9772 | T12: 11114 | U12: 9389 | V12: 11114 | W12: 51 | X12: 40 | Y12: 93 | Z12: 83 | AA12: 97 | AB12: 55 | AC12: 82 | AD12: 50 | AE12: 3 | AF12: 1 | AG12: 2 | AH12: 3 | AI12: 1 | AJ12: 18.66
A13: 2028 | B13: DEC | C13: 12 | D13: 12 | E13: 3200 | F13: 3200 | G13: 3300 | H13: 2310 | I13: 387 | J13: 1038 | K13: 554 | L13: 581 | M13: 640 | N13: 494 | O13: 788 | P13: 567 | Q13: 461 | R13: 10895 | S13: 7118 | T13: 4067 | U13: 7808 | V13: 9152 | W13: 81 | X13: 63 | Y13: 83 | Z13: 59 | AA13: 51 | AB13: 79 | AC13: 88 | AD13: 79 | AE13: 3 | AF13: 2 | AG13: 2 | AH13: 2 | AI13: 1 | AJ13: 18.71
... A37: 2030 | B37: DEC | C37: 12 | D37: 36 | E37: 2566 | F37: 3800 | G37: 100000 | H37: 78100 | I37: 961 | J37: 387 | K37: 760 | L37: 932 | M37: 760 | N37: 21342 | O37: 19177 | P37: 21961 | Q37: 15620 | R37: 16536 | S37: 6378 | T37: 7559 | U37: 9273 | V37: 6614 | W37: 86 | X37: 69 | Y37: 58 | Z37: 77 | AA37: 56 | AB37: 88 | AC37: 72 | AD37: 42 | AE37: 6 | AF37: 4 | AG37: 1 | AH37: 3 | AI37: 3 | AJ37: 33.15

Sheet Resources
B1: Colors | C1: Position | D1: Angle | E1: Transparency | G1: Shadow | O1: $#,##0;-$#,##0;0 | R1: [>=1000]0,"k";[<=-1000]-0,"k";0
B2: #5D30B6 | D2: https://exceltable.com/
B3: #4A278F
B4: #0A0616
B5: #0066FF
B7: #4A278F
B8: #130E2C
B9: #221054
B10: #5D468C
B11: #C59DF5
B13: #140C2E
B15: #A514F6
B16: #00BFFF
B17: #405390
